<?xml version="1.0" ?>
<!-- =================================================================================== -->
<!-- |    This document was autogenerated by xacro from src/ackermann_pipeline/urdf/ack_urdf.xacro | -->
<!-- |    EDITING THIS FILE BY HAND IS NOT RECOMMENDED                                 | -->
<!-- =================================================================================== -->
<robot name="ackerman_simple">
  <!-- ================= BASE ================= -->
  <link name="base_footprint"/>
  <link name="base_link">
    <inertial>
      <origin rpy="0 0 0" xyz="0.0115 0 0.0687"/>
      <mass value="1.8886"/>
      <inertia ixx="0.00576" ixy="0.0" ixz="0.000003" iyy="0.01878" iyz="0.0" izz="0.02437"/>
    </inertial>
    <visual>
      <origin rpy="0 0 0" xyz="0.01 0 0.05"/>
      <geometry>
        <box size="0.35 0.15 0.08"/>
      </geometry>
      <material name="blue">
        <color rgba="0.2 0.2 0.8 1"/>
      </material>
    </visual>
    <collision>
      <origin rpy="0 0 0" xyz="0.01 0 0.05"/>
      <geometry>
        <box size="0.35 0.15 0.08"/>
      </geometry>
    </collision>
  </link>
  <joint name="base_joint" type="fixed">
    <origin rpy="0 0 0" xyz="-0.0117 0 0.02677"/>
    <parent link="base_footprint"/>
    <child link="base_link"/>
  </joint>
  <!-- ================= FRONT LEFT STEERING & WHEEL ================= -->
  <link name="FL_STEERING_LINK">
    <inertial>
      <origin rpy="0 0 0" xyz="-0.0029 0 0"/>
      <mass value="0.0038"/>
      <inertia ixx="0.0000003" ixy="0" ixz="0" iyy="0.0000006" iyz="0" izz="0.0000003"/>
    </inertial>
  </link>
  <joint name="FL_STEERING_JOINT" type="revolute">
    <origin rpy="0 0 0" xyz="0.16174 0.085 0.0235"/>
    <parent link="base_link"/>
    <child link="FL_STEERING_LINK"/>
    <axis xyz="0 0 1"/>
    <limit effort="5" lower="-0.524" upper="0.524" velocity="3"/>
  </joint>
  <link name="FL_WHEEL_LINK">
    <inertial>
      <origin rpy="0 0 0" xyz="0 0 0"/>
      <mass value="0.0635"/>
      <inertia ixx="0.000046" ixy="0" ixz="0" iyy="0.000089" iyz="0" izz="0.000046"/>
    </inertial>
    <visual>
      <origin rpy="1.57079632679 0 0" xyz="0 0 0"/>
      <geometry>
        <cylinder length="0.03" radius="0.05027"/>
      </geometry>
      <material name="black">
        <color rgba="0.1 0.1 0.1 1"/>
      </material>
    </visual>
    <collision>
      <origin rpy="1.57079632679 0 0" xyz="0 0 0"/>
      <geometry>
        <cylinder length="0.03" radius="0.05027"/>
      </geometry>
    </collision>
  </link>
  <joint name="FL_WHEEL_JOINT" type="continuous">
    <origin rpy="0 0 0" xyz="0 0.0245 0"/>
    <parent link="FL_STEERING_LINK"/>
    <child link="FL_WHEEL_LINK"/>
    <axis xyz="0 1 0"/>
  </joint>
  <!-- ================= FRONT RIGHT STEERING & WHEEL ================= -->
  <link name="FR_STEERING_LINK">
    <inertial>
      <origin rpy="0 0 0" xyz="0.0015 0 0"/>
      <mass value="0.0047"/>
      <inertia ixx="0.0000003" ixy="0" ixz="0" iyy="0.000001" iyz="0" izz="0.0000007"/>
    </inertial>
  </link>
  <joint name="FR_STEERING_JOINT" type="revolute">
    <origin rpy="0 0 0" xyz="0.16174 -0.085 0.0235"/>
    <parent link="base_link"/>
    <child link="FR_STEERING_LINK"/>
    <axis xyz="0 0 1"/>
    <limit effort="5" lower="-0.524" upper="0.524" velocity="3"/>
    <mimic joint="FL_STEERING_JOINT" multiplier="1.0" offset="0.0"/>
  </joint>
  <link name="FR_WHEEL_LINK">
    <inertial>
      <origin rpy="0 0 0" xyz="0 0 0"/>
      <mass value="0.0635"/>
      <inertia ixx="0.000046" ixy="0" ixz="0" iyy="0.000089" iyz="0" izz="0.000046"/>
    </inertial>
    <visual>
      <origin rpy="1.57079632679 0 0" xyz="0 0 0"/>
      <geometry>
        <cylinder length="0.03" radius="0.05027"/>
      </geometry>
      <material name="black">
        <color rgba="0.1 0.1 0.1 1"/>
      </material>
    </visual>
    <collision>
      <origin rpy="1.57079632679 0 0" xyz="0 0 0"/>
      <geometry>
        <cylinder length="0.03" radius="0.05027"/>
      </geometry>
    </collision>
  </link>
  <joint name="FR_WHEEL_JOINT" type="continuous">
    <origin rpy="0 0 0" xyz="0 -0.0245 0"/>
    <parent link="FR_STEERING_LINK"/>
    <child link="FR_WHEEL_LINK"/>
    <axis xyz="0 1 0"/>
  </joint>
  <!-- ================= REAR LEFT WHEEL ================= -->
  <link name="BL_WHEEL_LINK">
    <inertial>
      <origin rpy="0 0 0" xyz="0 0 0"/>
      <mass value="0.0616"/>
      <inertia ixx="0.000046" ixy="0" ixz="0" iyy="0.000089" iyz="0" izz="0.000046"/>
    </inertial>
    <visual>
      <origin rpy="1.57079632679 0 0" xyz="0 0 0"/>
      <geometry>
        <cylinder length="0.03" radius="0.05027"/>
      </geometry>
      <material name="black">
        <color rgba="0.1 0.1 0.1 1"/>
      </material>
    </visual>
    <collision>
      <origin rpy="1.57079632679 0 0" xyz="0 0 0"/>
      <geometry>
        <cylinder length="0.03" radius="0.05027"/>
      </geometry>
    </collision>
  </link>
  <joint name="BL_WHEEL_JOINT" type="continuous">
    <origin rpy="0 0 0" xyz="-0.13328 0.1093 0.02075"/>
    <parent link="base_link"/>
    <child link="BL_WHEEL_LINK"/>
    <axis xyz="0 1 0"/>
  </joint>
  <!-- ================= REAR RIGHT WHEEL ================= -->
  <link name="BR_WHEEL_LINK">
    <inertial>
      <origin rpy="0 0 0" xyz="0 0 0"/>
      <mass value="0.0616"/>
      <inertia ixx="0.000046" ixy="0" ixz="0" iyy="0.000089" iyz="0" izz="0.000046"/>
    </inertial>
    <visual>
      <origin rpy="1.57079632679 0 0" xyz="0 0 0"/>
      <geometry>
        <cylinder length="0.03" radius="0.05027"/>
      </geometry>
      <material name="black">
        <color rgba="0.1 0.1 0.1 1"/>
      </material>
    </visual>
    <collision>
      <origin rpy="1.57079632679 0 0" xyz="0 0 0"/>
      <geometry>
        <cylinder length="0.03" radius="0.05027"/>
      </geometry>
    </collision>
  </link>
  <joint name="BR_WHEEL_JOINT" type="continuous">
    <origin rpy="0 0 0" xyz="-0.13328 -0.1093 0.02075"/>
    <parent link="base_link"/>
    <child link="BR_WHEEL_LINK"/>
    <axis xyz="0 1 0"/>
  </joint>
  <!-- ================= CAMERA ================= -->
  <link name="CAMERA_LINK">
    <inertial>
      <origin rpy="0 0 0" xyz="0 0 0"/>
      <mass value="0.0548"/>
      <inertia ixx="0.000069" ixy="0" ixz="0" iyy="0.000004" iyz="0" izz="0.000066"/>
    </inertial>
    <visual>
      <origin rpy="0 0 0" xyz="0 0 0"/>
      <geometry>
        <box size="0.02 0.06 0.02"/>
      </geometry>
      <material name="red">
        <color rgba="0.8 0.1 0.1 1"/>
      </material>
    </visual>
    <collision>
      <origin rpy="0 0 0" xyz="0 0 0"/>
      <geometry>
        <box size="0.02 0.06 0.02"/>
      </geometry>
    </collision>
  </link>
  <joint name="CAMERA_JOINT" type="fixed">
    <origin rpy="0 0.1 0" xyz="0.15 0.0 0.2"/>
    <parent link="base_link"/>
    <child link="CAMERA_LINK"/>
  </joint>
  <!-- ================= GAZEBO PLUGINS ================= -->
  <!-- Ackermann Drive Plugin -->
  <gazebo>
    <plugin filename="gz-sim-ackermann-steering-system" name="gz::sim::systems::AckermannSteering">
      <left_joint>FL_WHEEL_JOINT</left_joint>
      <right_joint>FR_WHEEL_JOINT</right_joint>
      <left_steering_joint>FL_STEERING_JOINT</left_steering_joint>
      <right_steering_joint>FR_STEERING_JOINT</right_steering_joint>
      <kingpin_width>0.17</kingpin_width>
      <steering_limit>0.524</steering_limit>
      <wheel_base>0.29502</wheel_base>
      <wheel_radius>0.05027</wheel_radius>
      <min_velocity>-2.0</min_velocity>
      <max_velocity>2.0</max_velocity>
      <min_acceleration>-1.0</min_acceleration>
      <max_acceleration>1.0</max_acceleration>
      <topic>/ackermann_cmd</topic>
      <odom_topic>/odom</odom_topic>
      <frame_id>odom</frame_id>
      <child_frame_id>base_footprint</child_frame_id>
      <odom_publish_frequency>50</odom_publish_frequency>
    </plugin>
  </gazebo>
  <!-- Mimic Joint Plugin (required for FR_STEERING to follow FL_STEERING) -->
  <gazebo>
    <plugin filename="gz-sim-mimic-joint-system" name="gz::sim::systems::MimicJoint">
      <joint>FR_STEERING_JOINT</joint>
      <mimicked_joint>FL_STEERING_JOINT</mimicked_joint>
      <multiplier>1.0</multiplier>
    </plugin>
  </gazebo>
  <!-- Camera Sensor Plugin -->
  <gazebo reference="CAMERA_LINK">
    <sensor name="camera" type="camera">
      <always_on>true</always_on>
      <update_rate>30</update_rate>
      <camera>
        <horizontal_fov>1.047</horizontal_fov>
        <image>
          <width>640</width>
          <height>480</height>
          <format>R8G8B8</format>
        </image>
        <clip>
          <near>0.1</near>
          <far>100</far>
        </clip>
      </camera>
      <topic>/camera/image</topic>
      <gz_frame_id>CAMERA_LINK</gz_frame_id>
    </sensor>
  </gazebo>
</robot>
